<?xml version="1.0"?>
<robot xmlns:xacro="http://www.ros.org/wiki/xacro">

    <xacro:include filename="inertial_macros.xacro"/>

    <link name="leg">
        <visual>
            <origin xyz="0.0 0.0 0.0" rpy="1.57 0.0 1.57"/>
            <geometry>
                <mesh filename="file://$(find project_eva)/meshes/EVA/leg.STL"/>
            </geometry>
            <material name="jeans">
                <color rgba="${66/255} ${93/255} ${140/255} 1.0"/>
            </material>
        </visual>

        <collision>
            <origin xyz="0.0 0.0 0.0" rpy="1.57 0.0 1.57"/>
            <geometry>
                <mesh filename="file://$(find project_eva)/meshes/EVA/leg.STL"/>
            </geometry>
            <material name="black">
            </material>
        </collision>

        <xacro:inertial_box mass="0.5" x="0.020" y="0.030" z="0.050" xyz="0 0 0.0515" rpy="0 0 0" />
    </link>

    <joint name="leg_joint" type="fixed">
        <parent link="EVA_base_link"/>
        <child link="leg"/>
        <origin xyz="0 0 0.59" rpy="0 0 0" />
    </joint>

    <link name="body">
        <visual>
            <origin xyz="0.0 0.0 0.0" rpy="1.57 0.0 1.57"/>
            <geometry>
                <mesh filename="file://$(find project_eva)/meshes/EVA/body.STL"/>
            </geometry>
            <material name="Top">
                <color rgba="${48/255} ${104/255} ${68/255} 1.0"/>
            </material>
        </visual>

        <collision>
            <origin xyz="0.0 0.0 0.0" rpy="1.57 0.0 1.57"/>
            <geometry>
                <mesh filename="file://$(find project_eva)/meshes/EVA/body.STL"/>
            </geometry>
        </collision>

        <xacro:inertial_box mass="0.50" x="0.05" y="0.086" z="0.05" xyz="0 0 0.25" rpy="0 0 0"/>
    </link>

    <joint name="body_joint" type="fixed">
        <parent link="leg"/>
        <child link="body"/>
        <origin xyz="0 0 0.103" rpy="0 0 0" />
    </joint>

    <link name="neck">
        <visual>
            <origin xyz="0.0 0.0 0.0" rpy="1.57 0 1.57"/>
            <geometry>
                <mesh filename="file://$(find project_eva)/meshes/EVA/neck.STL"/>
            </geometry>
            <material name="skin">
                <color rgba="${255/255} ${219/255} ${184/255} 1.0"/>
            </material>
        </visual>

        <collision>
            <origin xyz="0.0 0.0 0.0" rpy="1.57 0 1.57"/>
            <geometry>
                <mesh filename="file://$(find project_eva)/meshes/EVA/neck.STL"/>
            </geometry>
        </collision>

        <xacro:inertial_cylinder mass="0.2" length="0.054" radius="0.03" xyz="0 0 0.027" rpy="0 0 0" />
    </link>

    <joint name="neck_joint" type="revolute">
        <axis xyz="0 0 1"/>
        <limit effort="0.1" lower="-1" upper="1" velocity="0.2"/>
        <parent link="body"/>
        <child link="neck"/>
        <origin xyz="0 0 0.5" rpy="0 0 0" />
    </joint>

    <link name="chin">
        <visual>
            <origin xyz="0.0 0.0 0.0" rpy="1.57 0 1.57"/>
            <geometry>
                <mesh filename="file://$(find project_eva)/meshes/EVA/chin.STL"/>
            </geometry>
            <material name="skin">
                <color rgba="${255/255} ${219/255} ${184/255} 1.0"/>
            </material>
        </visual>

        <collision>
            <origin xyz="0.0 0.0 0.0" rpy="1.57 0 1.57"/>
            <geometry>
                <mesh filename="file://$(find project_eva)/meshes/EVA/chin.STL"/>
            </geometry>
        </collision>

        <xacro:inertial_cylinder mass="1.0" length="0.05" radius="0.05" xyz="0 0 0.05" rpy="0 0 0" />

    </link>

    <joint name="head_joint" type="revolute">
        <axis xyz="0 1 0"/>
        <limit effort="0.1" lower="-.51" upper="0.38" velocity="0.2"/>
        <parent link="neck"/>
        <child link="chin"/>
        <origin xyz="0 0 0.054" rpy="0 0 0" />
    </joint>

</robot>