<?xml version="1.0"?>
<robot xmlns:xacro="http://www.ros.org/wiki/xacro">

    <xacro:include filename="inertial_macros.xacro"/>

    <xacro:property name="wheel_mass" value="0.650"/>
    <xacro:property name="wheel_radius" value="0.0635"/>
    <xacro:property name="wheel_thickness" value="0.039"/>

    <xacro:macro name="wheel" params="parent child xyz rpy">

        <link name="${child}_wheel_link">

            <visual>
                <origin xyz="0.0 0.0 -0.035" rpy="3.14 0.0 0.0"/>
                <geometry>
                    <mesh filename="file://$(find project_eva)/meshes/Drive/Omni_Wheel.STL"/>
                    <!-- <cylinder radius="${wheel_radius}" length="${wheel_thickness}"/> -->
                </geometry>
                <material name="Black">
                    <color rgba="0.0 0.0 0.0 1.0"/>
                </material>
            </visual>

            <collision>
                <origin xyz="0.0 0.0 -0.01" rpy="3.14 0.0 0.0"/>
                <geometry>
                    <!-- <mesh filename="file://$(find project_eva)/meshes/Drive/Omni_Wheel.STL"/> -->
                    <cylinder radius="${wheel_radius}" length="${wheel_thickness}"/>
                    <!-- <sphere radius="${wheel_radius}"/> -->
                </geometry>
            </collision>

            <xacro:inertial_cylinder mass="${wheel_mass}" length="${wheel_thickness}" radius="${wheel_radius}" xyz="0 0 0" rpy="0 0 0">
            </xacro:inertial_cylinder>
        </link>

        <gazebo reference="${child}_wheel_link">
            <kp>10000.0</kp>
            <kd>100</kd>
            <mu1>3</mu1>
            <mu2>0.6</mu2> 
            <fdir1>0 1 0</fdir1>
            <fdir2>0 1 0</fdir2>
            <maxVel>10.0</maxVel>
            <minDepth>0</minDepth>
            <material>Gazebo/FlatBlack</material> 
        </gazebo>    
    
        <!-- <gazebo reference="${child}_wheel_joint">
            <implicitSpringDamper>1</implicitSpringDamper>
        </gazebo> -->

        <joint name="${child}_wheel_joint" type="continuous">
            <parent link="${parent}"/>
            <child link="${child}_wheel_link"/>
            <origin xyz="${xyz}" rpy="${rpy}" />
            <axis xyz="0.0 0.0 1.0" />
            <!-- <dynamics damping="5.0" friction="5.0"/> -->
        </joint>

    </xacro:macro>

    <xacro:macro name="default_wheel_transmission" params="name">
        <transmission name="${name}_transmission">
            <plugin>transmission_interface/SimpleTransmission</plugin>
            <actuator name="${name}_motor" role="actuator1"/>
            <joint name="${name}_wheel_joint"  role="joint1">
                <mechanical_reduction>1.0</mechanical_reduction>
            </joint>
        </transmission>
    </xacro:macro>

</robot>